Workbook

Sheet 안내
A1: 시멘트 통합 품질관리 시스템(QMS) — 관리항목·기준 정의서
A2: 작성: 품질관리팀 · 생성일 2026-10-28 · 시스템 설정(qms/standards.py, qms/knowledge.py)에서 자동 생성
A4: 목적 | B4: QMS가 감시·알림·진단에 사용하는 관리항목, KS 규격, 사내 관리기준, 알림 규칙, 원인진단 지식베이스를 한 문서로 정의한다. 공장 실제 기준으로 확정한 값을 '관리항목' 시트의 노란 칸에 입력하면 시스템 설정(⚙️ 기준·알림 설정)에 반영한다.
A5: 작성 방법(입력 칸) | B5: '관리항목' 시트의 노란색 칸(사내 하한·상한·목표 '확정값')만 입력한다. 비워 두면 회색 칸의 시스템 초기값을 계속 사용한다.
A6: 범례 — 노란 칸 | B6: 공장이 입력할 확정값
A7: 범례 — 회색 칸 | B7: 시스템 초기값: 업계 경험칙 기반(추정). 공장 데이터·실험으로 검증 후 확정 필요
A8: 범례 — 파란 글씨 | B8: KS 규격값(외부 근거). 수정 대상 아님 — 근거는 'KS규격_근거' 시트
A9: 작성 예시 | B9: 예) 클링커 자유석회(f-CaO): 확정 하한 0.5 / 확정 상한 1.6 / 확정 목표 1.1 ← 숫자만 입력(단위 제외)
A10: 사실/추정 구분 | B10: KS 값 = 규격(사실, 원문 대조 권장) · 사내 초기값·지식베이스 수치 = 경험칙(추정) · 진단 판정 '데이터 지지' = 측정 데이터로 확인된 변화(사실)
A11: 시트 구성 | B11: 요약 · 관리항목 · 알림규칙 · SPC판정규칙 · 원인진단_지식베이스 · 데이터입력_항목 · KS규격_근거 · 구축로드맵

Sheet 요약
A1: 관리항목 요약 — 공정별 현황 (수식으로 '관리항목' 시트에서 자동 집계)
A3: 공정 | B3: 관리항목 수(행) | C3: KS 기준 보유 | D3: 핵심관리항목 | E3: SPC 적용 | F3: 확정값 입력 완료 | G3: 확정 진행률
A4: 원료 | B4: =COUNTIF(관리항목!$B$2:$B$84,A4) | C4: =COUNTIFS(관리항목!$B$2:$B$84,A4,관리항목!$J$2:$J$84,"<>")+COUNTIFS(관리항목!$B$2:$B$84,A4,관리항목!$J$2:$J$84,"",관리항목!$K$2:$K$84,"<>") | D4: =COUNTIFS(관리항목!$B$2:$B$84,A4,관리항목!$U$2:$U$84,"●") | E4: =COUNTIFS(관리항목!$B$2:$B$84,A4,관리항목!$T$2:$T$84,"<>-") | F4: =SUMPRODUCT((관리항목!$B$2:$B$84=A4)*((LEN(관리항목!$Q$2:$Q$84)+LEN(관리항목!$R$2:$R$84)+LEN(관리항목!$S$2:$S$84))>0)) | G4: =IFERROR(F4/B4,0)
A5: 소성(킬른) | B5: =COUNTIF(관리항목!$B$2:$B$84,A5) | C5: =COUNTIFS(관리항목!$B$2:$B$84,A5,관리항목!$J$2:$J$84,"<>")+COUNTIFS(관리항목!$B$2:$B$84,A5,관리항목!$J$2:$J$84,"",관리항목!$K$2:$K$84,"<>") | D5: =COUNTIFS(관리항목!$B$2:$B$84,A5,관리항목!$U$2:$U$84,"●") | E5: =COUNTIFS(관리항목!$B$2:$B$84,A5,관리항목!$T$2:$T$84,"<>-") | F5: =SUMPRODUCT((관리항목!$B$2:$B$84=A5)*((LEN(관리항목!$Q$2:$Q$84)+LEN(관리항목!$R$2:$R$84)+LEN(관리항목!$S$2:$S$84))>0)) | G5: =IFERROR(F5/B5,0)
A6: 클링커 | B6: =COUNTIF(관리항목!$B$2:$B$84,A6) | C6: =COUNTIFS(관리항목!$B$2:$B$84,A6,관리항목!$J$2:$J$84,"<>")+COUNTIFS(관리항목!$B$2:$B$84,A6,관리항목!$J$2:$J$84,"",관리항목!$K$2:$K$84,"<>") | D6: =COUNTIFS(관리항목!$B$2:$B$84,A6,관리항목!$U$2:$U$84,"●") | E6: =COUNTIFS(관리항목!$B$2:$B$84,A6,관리항목!$T$2:$T$84,"<>-") | F6: =SUMPRODUCT((관리항목!$B$2:$B$84=A6)*((LEN(관리항목!$Q$2:$Q$84)+LEN(관리항목!$R$2:$R$84)+LEN(관리항목!$S$2:$S$84))>0)) | G6: =IFERROR(F6/B6,0)
A7: 시멘트(분쇄) | B7: =COUNTIF(관리항목!$B$2:$B$84,A7) | C7: =COUNTIFS(관리항목!$B$2:$B$84,A7,관리항목!$J$2:$J$84,"<>")+COUNTIFS(관리항목!$B$2:$B$84,A7,관리항목!$J$2:$J$84,"",관리항목!$K$2:$K$84,"<>") | D7: =COUNTIFS(관리항목!$B$2:$B$84,A7,관리항목!$U$2:$U$84,"●") | E7: =COUNTIFS(관리항목!$B$2:$B$84,A7,관리항목!$T$2:$T$84,"<>-") | F7: =SUMPRODUCT((관리항목!$B$2:$B$84=A7)*((LEN(관리항목!$Q$2:$Q$84)+LEN(관리항목!$R$2:$R$84)+LEN(관리항목!$S$2:$S$84))>0)) | G7: =IFERROR(F7/B7,0)
A8: 제품 물성 | B8: =COUNTIF(관리항목!$B$2:$B$84,A8) | C8: =COUNTIFS(관리항목!$B$2:$B$84,A8,관리항목!$J$2:$J$84,"<>")+COUNTIFS(관리항목!$B$2:$B$84,A8,관리항목!$J$2:$J$84,"",관리항목!$K$2:$K$84,"<>") | D8: =COUNTIFS(관리항목!$B$2:$B$84,A8,관리항목!$U$2:$U$84,"●") | E8: =COUNTIFS(관리항목!$B$2:$B$84,A8,관리항목!$T$2:$T$84,"<>-") | F8: =SUMPRODUCT((관리항목!$B$2:$B$84=A8)*((LEN(관리항목!$Q$2:$Q$84)+LEN(관리항목!$R$2:$R$84)+LEN(관리항목!$S$2:$S$84))>0)) | G8: =IFERROR(F8/B8,0)
A9: 시험 조건 | B9: =COUNTIF(관리항목!$B$2:$B$84,A9) | C9: =COUNTIFS(관리항목!$B$2:$B$84,A9,관리항목!$J$2:$J$84,"<>")+COUNTIFS(관리항목!$B$2:$B$84,A9,관리항목!$J$2:$J$84,"",관리항목!$K$2:$K$84,"<>") | D9: =COUNTIFS(관리항목!$B$2:$B$84,A9,관리항목!$U$2:$U$84,"●") | E9: =COUNTIFS(관리항목!$B$2:$B$84,A9,관리항목!$T$2:$T$84,"<>-") | F9: =SUMPRODUCT((관리항목!$B$2:$B$84=A9)*((LEN(관리항목!$Q$2:$Q$84)+LEN(관리항목!$R$2:$R$84)+LEN(관리항목!$S$2:$S$84))>0)) | G9: =IFERROR(F9/B9,0)
A10: 합계 | B10: =SUM(B4:B9) | C10: =SUM(C4:C9) | D10: =SUM(D4:D9) | E10: =SUM(E4:E9) | F10: =SUM(F4:F9) | G10: =IFERROR(F10/B10,0)
A12: ※ '관리항목 수(행)'은 품종별 기준을 따로 세므로 항목 수보다 많을 수 있음. KS 기준 보유 = KS 하한 또는 상한이 있는 행.

Sheet 관리항목
A1: No | B1: 공정 | C1: 코드 | D1: 항목 | E1: 단위 | F1: 측정 주기 | G1: 데이터 출처 | H1: 시험방법 | I1: 품종 | J1: KS 하한 | K1: KS 상한 | L1: KS 근거 | M1: 사내 하한(초기) | N1: 사내 상한(초기) | O1: 목표(초기) | P1: 초기값 근거 | Q1: 사내 하한(확정) | R1: 사내 상한(확정) | S1: 목표(확정) | T1: SPC 판정규칙 | U1: 핵심관리 | V1: 설명
A2: 1 | B2: 원료 | C2: rm_cao | D2: 원료 CaO | E2: % | F2: 2시간 | G2: XRF(시험실/온라인)·잔사 시험 | H2: - | I2: 전 품종 | L2: - | P2: 모니터링 항목(기준 미설정) | T2: -
A3: 2 | B3: 원료 | C3: rm_sio2 | D3: 원료 SiO₂ | E3: % | F3: 2시간 | G3: XRF(시험실/온라인)·잔사 시험 | H3: - | I3: 전 품종 | L3: - | P3: 모니터링 항목(기준 미설정) | T3: -
A4: 3 | B4: 원료 | C4: rm_al2o3 | D4: 원료 Al₂O₃ | E4: % | F4: 2시간 | G4: XRF(시험실/온라인)·잔사 시험 | H4: - | I4: 전 품종 | L4: - | P4: 모니터링 항목(기준 미설정) | T4: -
A5: 4 | B5: 원료 | C5: rm_fe2o3 | D5: 원료 Fe₂O₃ | E5: % | F5: 2시간 | G5: XRF(시험실/온라인)·잔사 시험 | H5: - | I5: 전 품종 | L5: - | P5: 모니터링 항목(기준 미설정) | T5: -
A6: 5 | B6: 원료 | C6: rm_so3 | D6: 원료 SO₃ | E6: % | F6: 2시간 | G6: XRF(시험실/온라인)·잔사 시험 | H6: - | I6: 전 품종 | L6: - | P6: 모니터링 항목(기준 미설정) | T6: -
A7: 6 | B7: 원료 | C7: rm_k2o | D7: 원료 K₂O | E7: % | F7: 2시간 | G7: XRF(시험실/온라인)·잔사 시험 | H7: - | I7: 전 품종 | L7: - | P7: 모니터링 항목(기준 미설정) | T7: -
A8: 7 | B8: 원료 | C8: rm_na2o | D8: 원료 Na₂O | E8: % | F8: 2시간 | G8: XRF(시험실/온라인)·잔사 시험 | H8: - | I8: 전 품종 | L8: - | P8: 모니터링 항목(기준 미설정) | T8: -
A9: 8 | B9: 원료 | C9: rm_mgo | D9: 원료 MgO | E9: % | F9: 2시간 | G9: XRF(시험실/온라인)·잔사 시험 | H9: - | I9: 전 품종 | L9: - | N9: 2.5 | P9: 경험칙 초기값 — 공장 기준으로 교체 필요 | T9: R1 | V9: 석회석 내 백운석(돌로마이트) 혼입 지표. 클링커 MgO≈원료×1.55
A10: 9 | B10: 원료 | C10: rm_lsf | D10: 원료 LSF | F10: 2시간 | G10: XRF(시험실/온라인)·잔사 시험 | H10: - | I10: 전 품종 | L10: - | M10: 97 | N10: 101 | O10: 99 | P10: 경험칙 초기값 — 공장 기준으로 교체 필요 | T10: R1, R2, R3, R5, R6 | U10: ● | V10: 석탄회 흡수로 클링커 LSF는 원료보다 약 3~4 낮아짐(공장별 상이)
A11: 10 | B11: 원료 | C11: rm_sm | D11: 원료 SM | F11: 2시간 | G11: XRF(시험실/온라인)·잔사 시험 | H11: - | I11: 전 품종 | L11: - | M11: 2.35 | N11: 2.75 | O11: 2.55 | P11: 경험칙 초기값 — 공장 기준으로 교체 필요 | T11: R1, R2, R3, R5, R6 | U11: ●
A12: 11 | B12: 원료 | C12: rm_im | D12: 원료 IM | F12: 2시간 | G12: XRF(시험실/온라인)·잔사 시험 | H12: - | I12: 전 품종 | L12: - | M12: 1.4 | N12: 1.8 | O12: 1.58 | P12: 경험칙 초기값 — 공장 기준으로 교체 필요 | T12: R1, R2, R3, R5, R6
A13: 12 | B13: 원료 | C13: rm_r90 | D13: 원료 90μm 잔사 | E13: % | F13: 2시간 | G13: XRF(시험실/온라인)·잔사 시험 | H13: - | I13: 전 품종 | L13: - | N13: 16 | O13: 13 | P13: 경험칙 초기값 — 공장 기준으로 교체 필요 | T13: R1, R2, R3, R5, R6 | U13: ● | V13: 조대 석영·방해석 입자 → 소성성 저하, f-CaO 상승
A14: 13 | B14: 원료 | C14: rm_r200 | D14: 원료 200μm 잔사 | E14: % | F14: 2시간 | G14: XRF(시험실/온라인)·잔사 시험 | H14: - | I14: 전 품종 | L14: - | N14: 1.5 | O14: 1 | P14: 경험칙 초기값 — 공장 기준으로 교체 필요 | T14: R1
A15: 14 | B15: 원료 | C15: rm_loi | D15: 원료 강열감량 | E15: % | F15: 2시간 | G15: XRF(시험실/온라인)·잔사 시험 | H15: KS L 5120(강열감량) | I15: 전 품종 | L15: - | P15: 모니터링 항목(기준 미설정) | T15: - | V15: 미측정 시 CO₂ 화학양론(0.785·CaO + 1.092·MgO)으로 추정해 클링커 예측에 사용
A16: 15 | B16: 소성(킬른) | C16: kiln_feed | D16: 원료 투입량 | E16: t/h | F16: 1시간 | G16: DCS(킬른 운전) | H16: - | I16: 전 품종 | L16: - | P16: 운전 변수(기준 미설정) | T16: -
A17: 16 | B17: 소성(킬른) | C17: coal_rate | D17: 석탄 투입량 | E17: t/h | F17: 1시간 | G17: DCS(킬른 운전) | H17: - | I17: 전 품종 | L17: - | P17: 운전 변수(기준 미설정) | T17: -
A18: 17 | B18: 소성(킬른) | C18: kiln_bzt | D18: 소성대 온도(파이로미터) | E18: ℃ | F18: 1시간 | G18: DCS(킬른 운전) | H18: - | I18: 전 품종 | L18: - | M18: 1380 | N18: 1470 | O18: 1420 | P18: 경험칙 초기값 — 공장 기준으로 교체 필요 | T18: R1 | U18: ● | V18: 측정 위치·방사율 설정에 따라 절대값이 공장마다 다름
A19: 18 | B19: 소성(킬른) | C19: kiln_o2 | D19: 킬른 입구 O₂ | E19: % | F19: 1시간 | G19: DCS(킬른 운전) | H19: - | I19: 전 품종 | L19: - | M19: 2 | N19: 4.5 | O19: 3 | P19: 경험칙 초기값 — 공장 기준으로 교체 필요 | T19: R1
A20: 19 | B20: 소성(킬른) | C20: kiln_co | D20: 킬른 입구 CO | E20: % | F20: 1시간 | G20: DCS(킬른 운전) | H20: - | I20: 전 품종 | L20: - | N20: 0.3 | O20: 0.05 | P20: 경험칙 초기값 — 공장 기준으로 교체 필요 | T20: - | U20: ● | V20: 환원 분위기 지표. 클링커 품질 저하·SO₃ 휘발·EP CO 트립 위험
A21: 20 | B21: 소성(킬른) | C21: kiln_torque | D21: 킬른 주모터 부하 | E21: % | F21: 1시간 | G21: DCS(킬른 운전) | H21: - | I21: 전 품종 | L21: - | P21: 운전 변수(기준 미설정) | T21: - | V21: 소성 상태·코팅 상태의 간접 지표
A22: 21 | B22: 소성(킬른) | C22: kiln_calc_temp | D22: 하소로 출구 온도 | E22: ℃ | F22: 1시간 | G22: DCS(킬른 운전) | H22: - | I22: 전 품종 | L22: - | M22: 855 | N22: 895 | O22: 875 | P22: 경험칙 초기값 — 공장 기준으로 교체 필요 | T22: R1
A23: 22 | B23: 소성(킬른) | C23: kiln_sec_air | D23: 2차 공기 온도 | E23: ℃ | F23: 1시간 | G23: DCS(킬른 운전) | H23: - | I23: 전 품종 | L23: - | M23: 950 | O23: 1050 | P23: 경험칙 초기값 — 공장 기준으로 교체 필요 | T23: R1
A24: 23 | B24: 클링커 | C24: clk_cao | D24: 클링커 CaO | E24: % | F24: 2시간 | G24: XRF·f-CaO·리터중량 시험 | H24: - | I24: 전 품종 | L24: - | P24: 모니터링 항목(기준 미설정) | T24: -
A25: 24 | B25: 클링커 | C25: clk_sio2 | D25: 클링커 SiO₂ | E25: % | F25: 2시간 | G25: XRF·f-CaO·리터중량 시험 | H25: - | I25: 전 품종 | L25: - | P25: 모니터링 항목(기준 미설정) | T25: -
A26: 25 | B26: 클링커 | C26: clk_al2o3 | D26: 클링커 Al₂O₃ | E26: % | F26: 2시간 | G26: XRF·f-CaO·리터중량 시험 | H26: - | I26: 전 품종 | L26: - | P26: 모니터링 항목(기준 미설정) | T26: -
A27: 26 | B27: 클링커 | C27: clk_fe2o3 | D27: 클링커 Fe₂O₃ | E27: % | F27: 2시간 | G27: XRF·f-CaO·리터중량 시험 | H27: - | I27: 전 품종 | L27: - | P27: 모니터링 항목(기준 미설정) | T27: -
A28: 27 | B28: 클링커 | C28: clk_so3 | D28: 클링커 SO₃ | E28: % | F28: 2시간 | G28: XRF·f-CaO·리터중량 시험 | H28: - | I28: 전 품종 | L28: - | P28: 모니터링 항목(기준 미설정) | T28: -
A29: 28 | B29: 클링커 | C29: clk_k2o | D29: 클링커 K₂O | E29: % | F29: 2시간 | G29: XRF·f-CaO·리터중량 시험 | H29: - | I29: 전 품종 | L29: - | P29: 모니터링 항목(기준 미설정) | T29: -
A30: 29 | B30: 클링커 | C30: clk_na2o | D30: 클링커 Na₂O | E30: % | F30: 2시간 | G30: XRF·f-CaO·리터중량 시험 | H30: - | I30: 전 품종 | L30: - | P30: 모니터링 항목(기준 미설정) | T30: -
A31: 30 | B31: 클링커 | C31: clk_c2s | D31: 클링커 C₂S | E31: % | F31: 2시간 | G31: XRF·f-CaO·리터중량 시험 | H31: - | I31: 전 품종 | L31: - | P31: 모니터링 항목(기준 미설정) | T31: -
A32: 31 | B32: 클링커 | C32: clk_c4af | D32: 클링커 C₄AF | E32: % | F32: 2시간 | G32: XRF·f-CaO·리터중량 시험 | H32: - | I32: 전 품종 | L32: - | P32: 모니터링 항목(기준 미설정) | T32: -
A33: 32 | B33: 클링커 | C33: clk_mgo | D33: 클링커 MgO | E33: % | F33: 2시간 | G33: XRF·f-CaO·리터중량 시험 | H33: - | I33: 전 품종 | L33: - | N33: 4.5 | P33: 경험칙 초기값 — 공장 기준으로 교체 필요 | T33: R1 | V33: KS 시멘트 MgO 5.0% 이하 대응. 페리클레이스 → 안정도 불량
A34: 33 | B34: 클링커 | C34: clk_fcao | D34: 클링커 자유석회(f-CaO) | E34: % | F34: 2시간 | G34: XRF·f-CaO·리터중량 시험 | H34: - | I34: 전 품종 | L34: - | M34: 0.4 | N34: 1.8 | O34: 1 | P34: 경험칙 초기값 — 공장 기준으로 교체 필요 | T34: R1, R2, R3, R5, R6 | U34: ● | V34: 소성 상태의 핵심 지표. 과고=소성 부족/LSF 과다, 과저=과소성(연료 낭비)
A35: 34 | B35: 클링커 | C35: clk_lw | D35: 클링커 리터중량 | E35: g/L | F35: 2시간 | G35: XRF·f-CaO·리터중량 시험 | H35: - | I35: 전 품종 | L35: - | M35: 1200 | N35: 1400 | O35: 1300 | P35: 경험칙 초기값 — 공장 기준으로 교체 필요 | T35: R1 | V35: 소성도 지표(측정 입도·방법에 따라 절대값 상이)
A36: 35 | B36: 클링커 | C36: clk_cl | D36: 클링커 Cl | E36: ppm | F36: 2시간 | G36: XRF·f-CaO·리터중량 시험 | H36: - | I36: 전 품종 | L36: - | P36: 모니터링 항목(기준 미설정) | T36: - | V36: 염소 — 바이패스·킬른 내 순환(코팅·링 형성) 지표
A37: 36 | B37: 클링커 | C37: clk_f | D37: 클링커 F | E37: ppm | F37: 2시간 | G37: XRF·f-CaO·리터중량 시험 | H37: - | I37: 전 품종 | L37: - | P37: 모니터링 항목(기준 미설정) | T37: - | V37: 불소 — 광화제. 과다 시 응결·초기강도 영향
A38: 37 | B38: 클링커 | C38: clk_temp | D38: 클링커 온도 | E38: ℃ | F38: 2시간 | G38: XRF·f-CaO·리터중량 시험 | H38: - | I38: 전 품종 | L38: - | P38: 모니터링 항목(기준 미설정) | T38: - | V38: 냉각기 출구 클링커 온도(냉각 상태 지표)
A39: 38 | B39: 클링커 | C39: clk_lsf | D39: 클링커 LSF | F39: 2시간 | G39: XRF·f-CaO·리터중량 시험 | H39: - | I39: 전 품종 | L39: - | M39: 93 | N39: 97.5 | O39: 95 | P39: 경험칙 초기값 — 공장 기준으로 교체 필요 | T39: R1, R2, R3, R5, R6 | U39: ●
A40: 39 | B40: 클링커 | C40: clk_sm | D40: 클링커 SM | F40: 2시간 | G40: XRF·f-CaO·리터중량 시험 | H40: - | I40: 전 품종 | L40: - | M40: 2.3 | N40: 2.7 | O40: 2.5 | P40: 경험칙 초기값 — 공장 기준으로 교체 필요 | T40: R1, R2, R3, R5, R6
...

Sheet 알림규칙
A1: 심각도 | B1: 판정 조건 | C1: 예시 | D1: 통보 대상(제안) | E1: 대응 기한(제안) | F1: 발송
A2: 🔴 위험 | B2: 제품 항목이 KS L 5201 규격을 벗어남 | C2: 시멘트 SO₃ 3.5% 초과(1종), 28일 강도 42.5 MPa 미만 | D2: 품질팀장·생산팀장·공장장 | E2: 즉시(1시간 내) 출하 판정 | F2: 메일+메신저 즉시
A3: 🟠 경고 | B3: 사내 관리기준 이탈 / 시험조건(KS L ISO 679) 이탈 / 28일 예측치 사내기준 미달 | C3: f-CaO 1.8% 초과, 분말도 3,250 미만, 양생수 19~21 ℃ 이탈 | D3: 품질 담당·해당 공정 담당 | E3: 당일(8시간 내) 원인 조사 | F3: 메일+메신저
A4: 🟡 주의 | B4: 규격 이내이나 SPC 판정규칙 위반(8시간 평균 기준 R1·R2·R3 등) | C4: 원료 LSF 9연속 중심선 위(평균 이동) | D4: 품질 담당 | E4: 3일 내 점검 | F4: 대시보드 표시(기본 미발송)
A5: 공통 | B5: 같은 항목·품종에서 12시간 이내(물성 3일 이내) 이어지는 위반점은 1건으로 묶음. 규격 이탈과 겹치는 SPC 패턴은 '동반 패턴'으로 기록 | C5: 알림 피로도 감소 | D5: - | E5: - | F5: -
A6: 예측 | B6: 예측값은 실측이 아니므로 최고 심각도를 '경고'로 제한 | C6: 28일 강도 예측 46 MPa → 경고(예측) | D6: - | E6: - | F6: -

Sheet SPC판정규칙
A1: 코드 | B1: 규칙 | C1: 의미 | D1: 기본 적용
A2: R1 | B2: 관리한계(±3σ) 이탈 | C2: 돌발 이상(한 점이 관리한계 밖) | D2: 활성(기본)
A3: R2 | B3: 중심선 한쪽 연속 9점(평균 이동) | C3: 공정 평균의 이동(shift) | D3: 활성(기본)
A4: R3 | B4: 연속 6점 상승/하강(추세) | C4: 점진적 추세(drift) | D4: 활성(기본)
A5: R5 | B5: 3점 중 2점 ±2σ 밖(같은 쪽) | C5: 중간 크기의 평균 이동 조기 감지 | D5: 선택(설정 화면에서 활성화)
A6: R6 | B6: 5점 중 4점 ±1σ 밖(같은 쪽) | C6: 작은 평균 이동 감지(허위경보 증가 주의) | D6: 선택(설정 화면에서 활성화)
A8: ※ 관리한계: 기준기간(기본 데이터 시작 30일) 평균 ± 3σ, σ = 기준기간 표준편차(자기상관 고려), 기준기간 내 3σ 밖 점은 1회 제외
A9: ※ 2시간·1시간 데이터는 8시간(근무조) 평균에 판정규칙 적용 — 원 데이터에 런 규칙을 적용하면 허위 경보 과다
A10: ※ 규격·관리기준 이탈은 개별 측정값 기준으로 판정
A11: ※ 공정능력: Cpk = 군내변동(MR̄/1.128), Ppk = 전체 표준편차 — 관용 기준 1.33 이상 충분, 1.0 미만 개선 필요

Sheet 원인진단_지식베이스
A1: 현상(항목·방향) | B1: 축 | C1: 원인 가설 | D1: 메커니즘 | E1: 자동 평가 데이터 | F1: 확인 방법(데이터·시험) | G1: 단기 조치 | H1: 근본 대책 | I1: 근거 수준 | J1: 담당(제안) | K1: 사전 가중치
A2: 28일 압축강도 저하 | B2: 공정 | C2: 분말도 저하·입도분포 조대화(분쇄 공정) | D2: 분말도는 수화 반응 표면적을 결정하며 특히 조기강도에 민감하다. 경험칙: Blaine 100 cm²/g 당 28일 강도 약 0.5~1 MPa. | E2: 시멘트 분말도(Blaine)↓, 시멘트 45μm 잔사↑ | F2: Blaine·45μm 잔사 재측정 / 레이저 입도분석(PSD, RRSB 균등계수 n) / 밀 운전 데이터(세퍼레이터 rpm·순환부하·투입량) | G2: 세퍼레이터 속도 상향·밀 투입량 감량으로 분말도 회복 / 분말도 미달 구간 제품 출하 보류·재시험 | H2: 분쇄 매체 충진율·마모 정기 관리 / 세퍼레이터 정비 주기 수립 / 분말도 자동제어(온라인 PSD 분석기) 도입 검토 | I2: 이론+경험칙 | J2: 생산(분쇄) | K2: 0.9
A3: 28일 압축강도 저하 | B3: 공정 | C3: 소성 부족(소성대 온도·열량 부족) | D3: 소성대 온도·체류시간 부족 시 C₂S + CaO → C₃S 반응이 완결되지 않아 f-CaO↑, C₃S↓, 클링커가 다공질(리터중량↓)이 된다. 그 결과 강도가 저하된다. | E3: 클링커 자유석회(f-CaO)↑, 소성대 온도(파이로미터)↓, 클링커 리터중량↓, 2차 공기 온도↓ | F3: 킬른 운전 추이(소성대 온도·주모터 부하·2차 공기 온도) 확인 / 시간대별 f-CaO·리터중량 대조 / 석탄 공업분석(발열량·회분·휘발분·수분) | G3: f-CaO 기준 초과 클링커 분리 저장 또는 혼합 비율 제한 / 소성 강화(연료·버너 조정) 및 원료 투입량 일시 감량 | H3: 석탄 입고 품질 기준(발열량 하한) 및 혼탄 관리 / f-CaO 기반 소성 피드백 운전 기준서 수립 / 버너 화염 형상 점검·개선 | I3: 이론+경험칙 | J3: 생산(소성) | K3: 1
A4: 28일 압축강도 저하 | B4: 화학 | C4: 클링커 C₃S 저하(광물 조성 변화) | D4: C₃S(알라이트)는 3~28일 강도의 주 기여 광물이다. 경험칙: C₃S 1%p 감소 시 28일 강도 약 0.3~0.5 MPa 감소(공장별 상이 — 자체 회귀분석으로 확인 필요). | E4: 클링커 C₃S(Bogue)↓, 클링커 LSF↓ | F4: 해당 기간 클링커 XRF 재분석·Bogue C₃S 확인 / XRD-Rietveld 정량으로 C₃S/C₂S 실측(Bogue와 편차 확인) / 클링커 현미경 관찰(알라이트 크기·형태, 벨라이트 군집) | G4: 분말도 상향(+100~150 cm²/g)으로 강도 보상(밀 생산성 저하 감수) / 해당 클링커 사용 제품의 3·7일 강도 추적 강화 | H4: 원료 LSF 목표·변동(σ) 관리 강화 / 소성 운전 기준(소성대 온도·O₂·f-CaO 피드백) 표준화 | I4: 이론+경험칙 | J4: 품질 | K4: 1
A5: 28일 압축강도 저하 | B5: 화학 | C5: SO₃(석고) 최적치 이탈 | D5: SO₃가 최적치에서 벗어나면 C₃A 수화 제어가 부적절해져 강도가 저하된다. 과다 시 응결 지연·지연 팽창 위험, 부족 시 급결·조기강도 저하. | E5: 시멘트 SO₃ 목표편차↑ | F5: SO₃ 재분석(XRF ↔ 중량법 KS L 5120 교차) / 석고 정량공급기 실적(설정 대비 실제) / SO₃ 수준별 모르타르 강도 최적화 시험 | G5: 석고 투입 설정 복귀 및 공급기 점검 / SO₃ 이탈 구간 제품 분리·추가 시험 | H5: 석고 공급기 정기 교정·막힘 감지 알람 / 품종별 최적 SO₃ 정기 재설정(분기 1회) | I5: 이론+경험칙 | J5: 생산(분쇄) | K5: 0.7
A6: 28일 압축강도 저하 | B6: 시험오차 | C6: 28일 강도 시험 조건 이탈·시험 오차 | D6: 강도는 양생 온도(20±1 ℃)·시험실 조건·공시체 성형·재하 속도에 민감하다(KS L ISO 679). 조기강도와 화학 성분이 정상인데 특정 재령만 낮으면 시험오차 가능성이 높다. | E6: 28일 실측−조기강도 예측 잔차↓, 양생수 온도 기준 이탈, 시험실 온도 기준 이탈, 시험실 상대습도 기준 이탈, sand_lot 변경 | F6: 양생수조 온도 기록 확인 / 예비 공시체 재시험 또는 보관 시료 재성형 / 재하 속도(2,400±200 N/s) 및 시험기 교정 상태 확인 / 표준사 Lot·성형자 변경 여부 확인 | G6: 해당 로트 결과 보류 후 재시험으로 확정 / 양생수조 온도 제어기 점검·수리 | H6: 양생조 온도 자동기록·이탈 알람(±1 ℃) / 시험자 간 비교시험(숙련도) 정기 실시 / 시험기 정기 교정 관리 | I6: 규격+경험칙 | J6: 품질(시험실) | K6: 0.8
A7: 28일 압축강도 저하 | B7: 원료 | C7: 원료 화학 변동 증가(LSF 변동성) | D7: 원료 LSF 변동이 크면 과소성·소성부족 구간이 혼재해 클링커 품질 편차가 커지고 평균 강도가 낮아진다. | E7: 원료 LSF 변동↑, 클링커 LSF 변동↑ | F7: 원료 LSF 시간대별 표준편차 확인 / 혼합사일로 레벨·혼합효과(입·출 σ 비) 확인 | G7: 원료 조합 제어 게인·샘플링 주기 점검 | H7: 원료 예비균질화(파일링) 운영 개선 / 원료밀 조합제어(XRF 온라인 피드백) 고도화 | I7: 경험칙 | J7: 생산(원료) | K7: 0.5
A8: 28일 압축강도 저하 | B8: 원료 | C8: 혼합재(석회석) 과다·클링커 풍화 | D8: 소량혼합성분(석회석) 증가 시 희석효과로 강도가 낮아진다. 강열감량 상승은 클링커 풍화(prehydration)·석고 결정수 영향일 수도 있다. | E8: 시멘트 강열감량↑ | F8: LOI·CO₂ 분석으로 석회석 혼입률 추정 / 혼합재 정량공급기 실적 확인 / 클링커 저장기간·야적 여부 확인 | G8: 혼합재 투입률 설정 복귀 | H8: 혼합재 투입 자동제어·실적 모니터링 / 클링커 저장 관리(선입선출·야적 최소화) | I8: 경험칙 | J8: 생산(분쇄) | K8: 0.5
A9: 28일 압축강도 저하 | B9: 설비 | C9: 클링커 냉각 불량(냉각기) | D9: 서랭 시 C₃S 분해·벨라이트 조대화·C₃A 결정화로 반응성이 낮아질 수 있다. 2차 공기 온도 저하는 냉각기 열회수 이상의 신호. | E9: 2차 공기 온도↓ | F9: 냉각기 그레이트 속도·냉각 팬 풍량 확인 / 냉각기 출구 클링커 온도 확인 / 클링커 현미경 관찰(알라이트 분해 흔적) | G9: 냉각기 운전 조건(그레이트 속도·풍량) 조정 | H9: 냉각기 정비(그레이트 플레이트·팬) 계획 반영 | I9: 문헌+경험칙 | J9: 설비 | K9: 0.35
A10: 28일 압축강도 저하 | B10: 화학 | C10: 알칼리 증가(후기강도 저하) | D10: 알칼리(Na₂Oeq) 증가는 조기강도를 높이지만 28일 이후 강도 발현을 저해하는 경향이 있다(문헌·경험칙). | E10: 클링커 등가알칼리↑ | F10: 클링커·시멘트 K₂O/Na₂O 분석 / 원료·연료 알칼리 투입량(바이패스 운전 여부) 확인 | G10: 바이패스 추기량 조정(설비 보유 시) | H10: 원료·대체연료 알칼리 투입 관리 기준 수립 | I10: 문헌+경험칙 | J10: 품질 | K10: 0.4
A11: 7일 압축강도 저하 | B11: 공정 | C11: 분말도 저하·입도분포 조대화(분쇄 공정) | D11: 분말도는 수화 반응 표면적을 결정하며 특히 조기강도에 민감하다. 경험칙: Blaine 100 cm²/g 당 3일 강도 약 1~1.5 MPa. | E11: 시멘트 분말도(Blaine)↓, 시멘트 45μm 잔사↑ | F11: Blaine·45μm 잔사 재측정 / 레이저 입도분석(PSD, RRSB 균등계수 n) / 밀 운전 데이터(세퍼레이터 rpm·순환부하·투입량) | G11: 세퍼레이터 속도 상향·밀 투입량 감량으로 분말도 회복 / 분말도 미달 구간 제품 출하 보류·재시험 | H11: 분쇄 매체 충진율·마모 정기 관리 / 세퍼레이터 정비 주기 수립 / 분말도 자동제어(온라인 PSD 분석기) 도입 검토 | I11: 이론+경험칙 | J11: 생산(분쇄) | K11: 1.3
A12: 7일 압축강도 저하 | B12: 공정 | C12: 소성 부족(소성대 온도·열량 부족) | D12: 소성대 온도·체류시간 부족 시 C₂S + CaO → C₃S 반응이 완결되지 않아 f-CaO↑, C₃S↓, 클링커가 다공질(리터중량↓)이 된다. 그 결과 강도가 저하된다. | E12: 클링커 자유석회(f-CaO)↑, 소성대 온도(파이로미터)↓, 클링커 리터중량↓, 2차 공기 온도↓ | F12: 킬른 운전 추이(소성대 온도·주모터 부하·2차 공기 온도) 확인 / 시간대별 f-CaO·리터중량 대조 / 석탄 공업분석(발열량·회분·휘발분·수분) | G12: f-CaO 기준 초과 클링커 분리 저장 또는 혼합 비율 제한 / 소성 강화(연료·버너 조정) 및 원료 투입량 일시 감량 | H12: 석탄 입고 품질 기준(발열량 하한) 및 혼탄 관리 / f-CaO 기반 소성 피드백 운전 기준서 수립 / 버너 화염 형상 점검·개선 | I12: 이론+경험칙 | J12: 생산(소성) | K12: 1
A13: 7일 압축강도 저하 | B13: 화학 | C13: 클링커 C₃S 저하(광물 조성 변화) | D13: C₃S(알라이트)는 3~28일 강도의 주 기여 광물이다. 경험칙: C₃S 1%p 감소 시 28일 강도 약 0.3~0.5 MPa 감소(공장별 상이 — 자체 회귀분석으로 확인 필요). | E13: 클링커 C₃S(Bogue)↓, 클링커 LSF↓ | F13: 해당 기간 클링커 XRF 재분석·Bogue C₃S 확인 / XRD-Rietveld 정량으로 C₃S/C₂S 실측(Bogue와 편차 확인) / 클링커 현미경 관찰(알라이트 크기·형태, 벨라이트 군집) | G13: 분말도 상향(+100~150 cm²/g)으로 강도 보상(밀 생산성 저하 감수) / 해당 클링커 사용 제품의 3·7일 강도 추적 강화 | H13: 원료 LSF 목표·변동(σ) 관리 강화 / 소성 운전 기준(소성대 온도·O₂·f-CaO 피드백) 표준화 | I13: 이론+경험칙 | J13: 품질 | K13: 1
... A159: 시험실 습도 이탈(시험조건) | B159: 시험오차 | C159: 기록 오류·센서 오차 | D159: 측정 센서 위치·교정 오차 또는 기록 누락. | E159: 이벤트 단발성↑ | F159: 기준 온도계로 비교 측정 | G159: 센서 재교정 | H159: 센서 이중화 | I159: 경험칙 | J159: 품질(시험실) | K159: 0.6
A161: ※ 메커니즘의 정량 수치(예: Blaine 100 cm²/g 당 강도 변화)는 업계 경험칙(추정)이며 공장 데이터로 검증 후 수정할 것. 사전 가중치 = 경험상 발생 빈도(1.0 보통).

Sheet 데이터입력_항목
A1: 엑셀 시트 | B1: 열 코드 | C1: 설명 | D1: 단위 | E1: 측정 주기 | F1: 필수
A2: 원료 | B2: timestamp | C2: 측정일시(예: 2026-10-07 14:00) | D2: - | E2: 2시간 | F2: 필수
A3: 원료 | B3: line | C3: line | D3: - | E3: 2시간 | F3: 선택
A4: 원료 | B4: grade | C4: grade | D4: - | E4: 2시간 | F4: 선택
A5: 원료 | B5: rm_cao | C5: 원료 CaO | D5: % | E5: 2시간 | F5: 선택
A6: 원료 | B6: rm_sio2 | C6: 원료 SiO₂ | D6: % | E6: 2시간 | F6: 선택
A7: 원료 | B7: rm_al2o3 | C7: 원료 Al₂O₃ | D7: % | E7: 2시간 | F7: 선택
A8: 원료 | B8: rm_fe2o3 | C8: 원료 Fe₂O₃ | D8: % | E8: 2시간 | F8: 선택
A9: 원료 | B9: rm_mgo | C9: 원료 MgO | D9: % | E9: 2시간 | F9: 선택
A10: 원료 | B10: rm_so3 | C10: 원료 SO₃ | D10: % | E10: 2시간 | F10: 선택
A11: 원료 | B11: rm_k2o | C11: 원료 K₂O | D11: % | E11: 2시간 | F11: 선택
A12: 원료 | B12: rm_na2o | C12: 원료 Na₂O | D12: % | E12: 2시간 | F12: 선택
... A97: 클링커일일 | B97: clk_crvi | C97: 클링커 수용성 Cr⁶⁺ | D97: mg/kg | E97: 1일 | F97: 선택
A99: ※ LSF·SM·IM·C₃S·액상량 등 파생값은 시스템이 자동 계산하므로 입력하지 않음. 같은 측정일시(+품종)는 값이 있는 칸만 덮어씀(빈 칸은 기존 값 유지 — LIMS 결과 순차 반영).

Sheet KS규격_근거
A1: 구분 | B1: 1종(보통) | C1: 3종(조강) | D1: 근거 | E1: 확인 상태
A2: 압축강도 1일 | B2: - | C2: 10.0 MPa 이상 | D2: KS L 5201 | E2: 웹 검색 확인(2026-10)
A3: 압축강도 3일 | B3: 12.5 MPa 이상 | C3: 20.0 MPa 이상 | D3: KS L 5201 | E3: 웹 검색 확인(2026-10)
A4: 압축강도 7일 | B4: 22.5 MPa 이상 | C4: 32.5 MPa 이상 | D4: KS L 5201 | E4: 웹 검색 확인(2026-10)
A5: 압축강도 28일 | B5: 42.5 MPa 이상 | C5: 47.5 MPa 이상 | D5: KS L 5201 | E5: 웹 검색 확인(2026-10)
A6: 분말도(비표면적) | B6: 2,800 cm²/g 이상 | C6: 3,300 cm²/g 이상 | D6: KS L 5201 (시험: KS L 5106) | E6: 웹 검색 확인(2026-10)
A7: 응결시간(비카) | B7: 초결 60분 이상, 종결 10시간 이하 | C7: 1종과 동일 적용 | D7: KS L 5201 (시험: KS L 5108) | E7: 1종 확인 · 3종 원문 대조 필요
A8: 안정도(오토클레이브 팽창도) | B8: 0.8% 이하 | C8: 0.8% 이하 | D8: KS L 5201 (시험: KS L 5107) | E8: 웹 검색 확인(2026-10)
A9: 산화마그네슘(MgO) | B9: 5.0% 이하 | C9: 5.0% 이하 | D9: KS L 5201 | E9: 웹 검색 확인(2026-10)
A10: 삼산화황(SO₃) | B10: 3.5% 이하 | C10: 4.5% 이하 | D10: KS L 5201 | E10: 웹 검색 확인(2026-10)
A11: 강열감량 | B11: 5.0% 이하 | C11: 5.0% 이하 | D11: KS L 5201 (2016 개정 3.0→5.0%) | E11: 웹 검색 확인(2026-10)
A12: 강도 시험조건 | B12: 시험실 20±2 ℃·RH 50% 이상, 양생수 20±1 ℃, 재하 2,400±200 N/s | C12: 동일 | D12: KS L ISO 679 (ISO 679) | E12: ISO 679 규정값 적용 — KS 원문 대조 필요
... A14: 수용성 6가크롬(EU 참고) | B14: 2 mg/kg 이하 | C14: 2 mg/kg 이하 | D14: EU REACH 부속서 XVII 47항(시험: EN 196-10) | E14: 시험법이 달라 국내 수치와 직접 비교 불가
A16: 출처: e나라표준인증 KS L 5201 https://standard.go.kr/KSCI/standardIntro/getStandardSearchView.do?ksNo=KSL5201
A17: 출처: 한국시멘트협회 KS 규격 요약 http://www.cement.or.kr/tech_2014/standard.asp?sm=3_6_1
A18: ※ 2종(중용열)·4종(저열)·5종(내황산염) 기준은 원문 확인 후 추가. KS는 개정될 수 있으므로 연 1회 최신판 대조 권장.

Sheet 구축로드맵
A1: 단계 | B1: 기간(추정) | C1: 주요 내용 | D1: 산출물 | E1: 필요 자원(추정) | F1: 상태
A2: 1단계 MVP | B2: 완료 | C2: 모니터링·3단계 기준·알림·5축 원인진단·28일 예측·보고서(PPT/엑셀)·엑셀 업로드·데모 데이터 | D2: Streamlit 시스템, 정의서, 구축 계획서 | E2: 품질 담당 1명 + 사내 PC 1대 | F2: 완료
A3: 2단계 확장 기능 | B3: 완료 | C3: 원료 배합 최적화(LSF·SM·IM·C₃S, 원가 최소)·클링커 계수·XRD 광물 예측, 재령별 강도·응결 예측과 제어 솔루션, 시멘트 6가크롬 물질수지·환원제 투입량, LIMS 연동(SQL·REST·파일), AI(Claude) 솔루션 보고서 | D3: 배합 설계서·6가크롬 평가표(엑셀), 기능 확장 보고(PPT) | E3: 품질 담당 1명 | F3: 개발 완료(실데이터 검증 필요)
A4: 3단계 실데이터 시범 | B4: 약 2~3개월 | C4: LIMS 실연결(읽기 전용 계정)·실데이터 3개월 적재 → 사내 기준·예측 모델·킬른 전환율·환원제 과잉계수 보정, 알림 채널 연결, AI 보고서 보안 승인 후 시범 사용 | D4: 확정 관리기준, 시범 운영 보고 | E4: IT·LIMS 담당 협조, 정보보안 승인 | F4: 예정
A5: 4단계 고도화 | B5: 약 3~6개월 | C5: 조치 이력 기반 지식베이스 학습, 입도분포(PSD) 반영 강도 모델, 원료 품위 예측 연계 배합 자동 보정 | D5: 고도화 기능, 효과 분석 | E5: 품질·생산·설비 협업 | F5: 계획
A6: 5단계 확산 | B6: 추후 | C6: DB/OPC-UA 실시간 연계, 모바일 알림, 타 공정·타 공장 확산 | D6: 운영 표준·교육 자료 | E6: IT 투자 검토 | F6: 계획
A8: ※ 기간·자원은 일반적인 시범 구축 경험에 따른 추정치이며, 데이터 연계 범위에 따라 달라짐.
